Workbook
Name Slicer_genre.genre: #N/A

Sheet movie
A1: MOV-ID | B1: title | C1: year | D1: parental_guide | E1: runtime | F1: gross_us_canada
A2: 0111161 | B2: The Shawshank Redemption | C2: 1994 | D2: R | E2: 142 | F2: $28,767,189
A3: 0068646 | B3: The Godfather | C3: 1972 | D3: R | E3: 175 | F3: $136,381,073
A4: 0468569 | B4: The Dark Knight | C4: 2008 | D4: PG-13 | E4: 152 | F4: $534,987,076
A5: 0071562 | B5: The Godfather Part II | C5: 1974 | D5: R | E5: 202 | F5: $47,834,595
A6: 0050083 | B6: 12 Angry Men | C6: 1957 | D6: Approved | E6: 96 | F6: $2,945
A7: 0167260 | B7: The Lord of the Rings: The Return of the King | C7: 2003 | D7: PG-13 | E7: 201 | F7: $381,878,219
A8: 0108052 | B8: Schindler's List | C8: 1993 | D8: R | E8: 195 | F8: $96,898,818
A9: 0120737 | B9: The Lord of the Rings: The Fellowship of the Ring | C9: 2001 | D9: PG-13 | E9: 178 | F9: $319,372,078
A10: 0110912 | B10: Pulp Fiction | C10: 1994 | D10: R | E10: 154 | F10: $107,928,762
A11: 0060196 | B11: The Good, the Bad and the Ugly | C11: 1966 | D11: R | E11: 178 | F11: $25,100,000
A12: 0109830 | B12: Forrest Gump | C12: 1994 | D12: PG-13 | E12: 142 | F12: $330,455,270
A13: 0167261 | B13: The Lord of the Rings: The Two Towers | C13: 2002 | D13: PG-13 | E13: 179 | F13: $345,518,923
... A69: 0361748 | B69: Inglourious Basterds | C69: 2009 | D69: R | E69: 153 | F69: $120,540,719
A70: 23849204 | B70: 12th Fail | C70: 2023 | D70: N/A | E70: 147 | F70: N/A
A71: 0090605 | B71: Aliens | C71: 1986 | D71: R | E71: 137 | F71: $85,160,248
A72: 1345836 | B72: The Dark Knight Rises | C72: 2012 | D72: PG-13 | E72: 164 | F72: $448,149,584
A73: 2380307 | B73: Coco | C73: 2017 | D73: PG | E73: 105 | F73: $210,460,015
A74: 0086879 | B74: Amadeus | C74: 1984 | D74: PG | E74: 160 | F74: $51,973,029
A75: 4154796 | B75: Avengers: Endgame | C75: 2019 | D75: PG-13 | E75: 181 | F75: $858,373,000
A76: 0119217 | B76: Good Will Hunting | C76: 1997 | D76: R | E76: 126 | F76: $138,433,435
A77: 0114709 | B77: Toy Story | C77: 1995 | D77: G | E77: 81 | F77: $227,280,221
A78: 0057565 | B78: High and Low | C78: 1963 | D78: Not Rated | E78: 143 | F78: $46,808
A79: 0364569 | B79: Oldboy | C79: 2003 | D79: R | E79: 120 | F79: $2,458,200
A80: 0057012 | B80: Dr. Strangelove or: How I Learned to Stop Worrying and Love the Bomb | C80: 1964 | D80: PG | E80: 95 | F80: $9,440,272
A81: 0082096 | B81: Das Boot | C81: 1981 | D81: N/A | E81: 149 | F81: $11,487,676
A82: 0112573 | B82: Braveheart | C82: 1995 | D82: R | E82: 178 | F82: $75,609,945
A83: 5311514 | B83: Your Name. | C83: 2016 | D83: N/A | E83: 106 | F83: $5,017,246
A84: 0119698 | B84: Princess Mononoke | C84: 1997 | D84: PG-13 | E84: 133 | F84: $11,696,687
A85: 0169547 | B85: American Beauty | C85: 1999 | D85: R | E85: 122 | F85: $130,096,601
A86: 1187043 | B86: 3 Idiots | C86: 2009 | D86: PG-13 | E86: 170 | F86: $6,532,874
A87: 7286456 | B87: Joker | C87: 2019 | D87: R | E87: 122 | F87: $335,477,657
A88: 8267604 | B88: Capernaum | C88: 2018 | D88: R | E88: 126 | F88: $1,661,096
A89: 0087843 | B89: Once Upon a Time in America | C89: 1984 | D89: R | E89: 229 | F89: $5,321,508
A90: 0045152 | B90: Singin' in the Rain | C90: 1952 | D90: G | E90: 103 | F90: $1,884,537
A91: 0091251 | B91: Come and See | C91: 1985 | D91: Not Rated | E91: 142 | F91: $16,053
A92: 0180093 | B92: Requiem for a Dream | C92: 2000 | D92: NC-17 | E92: 102 | F92: $3,635,482
A93: 0086190 | B93: Star Wars: Episode VI - Return of the Jedi | C93: 1983 | D93: PG | E93: 131 | F93: $316,566,101
A94: 0435761 | B94: Toy Story 3 | C94: 2010 | D94: G | E94: 103 | F94: $415,004,880
A95: 2106476 | B95: The Hunt | C95: 2012 | D95: R | E95: 115 | F95: $613,308
...

Sheet genre
A1: MOV-ID | B1: genre
A2: 111161 | B2: Epic
A3: 111161 | B3: Period Drama
A4: 111161 | B4: Prison Drama
A5: 111161 | B5: Drama
A6: 68646 | B6: Epic
A7: 68646 | B7: Gangster
A8: 68646 | B8: Tragedy
A9: 68646 | B9: Crime
A10: 68646 | B10: Drama
A11: 468569 | B11: Action Epic
A12: 468569 | B12: Epic
A13: 468569 | B13: Superhero
... A1645: 1454029 | B1645: Drama

Sheet director
A1: MOV-ID | B1: director_ID | C1: director
A2: 111161 | B2: 1104 | C2: Frank Darabont
A3: 68646 | B3: 338 | C3: Francis Ford Coppola
A4: 468569 | B4: 634240 | C4: Christopher Nolan
A5: 71562 | B5: 338 | C5: Francis Ford Coppola
A6: 50083 | B6: 1486 | C6: Sidney Lumet
A7: 167260 | B7: 1392 | C7: Peter Jackson
A8: 108052 | B8: 229 | C8: Steven Spielberg
A9: 120737 | B9: 1392 | C9: Peter Jackson
A10: 110912 | B10: 233 | C10: Quentin Tarantino
A11: 60196 | B11: 1466 | C11: Sergio Leone
A12: 109830 | B12: 709 | C12: Robert Zemeckis
A13: 167261 | B13: 1392 | C13: Peter Jackson
... A279: 1454029 | B279: 853238 | C279: Tate Taylor

Sheet writer
A1: MOV-ID | B1: writer_ID | C1: writer
A2: 111161 | B2: 175 | C2: Stephen King
A3: 111161 | B3: 1104 | C3: Frank Darabont
A4: 68646 | B4: 701374 | C4: Mario Puzo
A5: 68646 | B5: 338 | C5: Francis Ford Coppola
A6: 468569 | B6: 634300 | C6: Jonathan Nolan
A7: 468569 | B7: 634240 | C7: Christopher Nolan
A8: 468569 | B8: 275286 | C8: David S. Goyer
A9: 71562 | B9: 338 | C9: Francis Ford Coppola
A10: 71562 | B10: 701374 | C10: Mario Puzo
A11: 50083 | B11: 741627 | C11: Reginald Rose
A12: 167260 | B12: 866058 | C12: J.R.R. Tolkien
A13: 167260 | B13: 909638 | C13: Fran Walsh
... A554: 1454029 | B554: 3543826 | C554: Kathryn Stockett

Sheet star
A1: MOV-ID | B1: star_ID | C1: star
A2: 111161 | B2: 209 | C2: Tim Robbins
A3: 111161 | B3: 151 | C3: Morgan Freeman
A4: 111161 | B4: 348409 | C4: Bob Gunton
A5: 68646 | B5: 8 | C5: Marlon Brando
A6: 68646 | B6: 199 | C6: Al Pacino
A7: 68646 | B7: 1001 | C7: James Caan
A8: 468569 | B8: 288 | C8: Christian Bale
A9: 468569 | B9: 5132 | C9: Heath Ledger
A10: 468569 | B10: 1173 | C10: Aaron Eckhart
A11: 71562 | B11: 199 | C11: Al Pacino
A12: 71562 | B12: 134 | C12: Robert De Niro
A13: 71562 | B13: 380 | C13: Robert Duvall
... A751: 1454029 | B751: 818055 | C751: Octavia Spencer

Sheet All Data
A1: MOV-ID | B1: title | C1: year | D1: parental_guide | E1: runtime | F1: gross_us_canada | G1: genre.genre | H1: director.director_ID | I1: director.director | J1: writer.writer_ID | K1: writer.writer | L1: star.star_ID | M1: star.star | N1: decade
A2: 4154796 | B2: Avengers: Endgame | C2: 2019 | D2: PG-13 | E2: 181 | F2: 858373000 | G2: Space Sci-Fi | H2: 751577 | I2: Anthony Russo | J2: 1321655 | K2: Christopher Markus | L2: 375 | M2: Robert Downey Jr. | N2: =INT(C2/10)*10 & "-" & INT(C2/10)*10+9 -> 2010-2019
A3: 4154796 | B3: Avengers: Endgame | C3: 2019 | D3: PG-13 | E3: 181 | F3: 858373000 | G3: Space Sci-Fi | H3: 751577 | I3: Anthony Russo | J3: 1321655 | K3: Christopher Markus | L3: 262635 | M3: Chris Evans | N3: =INT(C3/10)*10 & "-" & INT(C3/10)*10+9 -> 2010-2019
A4: 4154796 | B4: Avengers: Endgame | C4: 2019 | D4: PG-13 | E4: 181 | F4: 858373000 | G4: Space Sci-Fi | H4: 751577 | I4: Anthony Russo | J4: 1321655 | K4: Christopher Markus | L4: 749263 | M4: Mark Ruffalo | N4: =INT(C4/10)*10 & "-" & INT(C4/10)*10+9 -> 2010-2019
A5: 4154796 | B5: Avengers: Endgame | C5: 2019 | D5: PG-13 | E5: 181 | F5: 858373000 | G5: Space Sci-Fi | H5: 751577 | I5: Anthony Russo | J5: 1321656 | K5: Stephen McFeely | L5: 375 | M5: Robert Downey Jr. | N5: =INT(C5/10)*10 & "-" & INT(C5/10)*10+9 -> 2010-2019
A6: 4154796 | B6: Avengers: Endgame | C6: 2019 | D6: PG-13 | E6: 181 | F6: 858373000 | G6: Space Sci-Fi | H6: 751577 | I6: Anthony Russo | J6: 1321656 | K6: Stephen McFeely | L6: 262635 | M6: Chris Evans | N6: =INT(C6/10)*10 & "-" & INT(C6/10)*10+9 -> 2010-2019
A7: 4154796 | B7: Avengers: Endgame | C7: 2019 | D7: PG-13 | E7: 181 | F7: 858373000 | G7: Space Sci-Fi | H7: 751577 | I7: Anthony Russo | J7: 1321656 | K7: Stephen McFeely | L7: 749263 | M7: Mark Ruffalo | N7: =INT(C7/10)*10 & "-" & INT(C7/10)*10+9 -> 2010-2019
A8: 4154796 | B8: Avengers: Endgame | C8: 2019 | D8: PG-13 | E8: 181 | F8: 858373000 | G8: Space Sci-Fi | H8: 751577 | I8: Anthony Russo | J8: 498278 | K8: Stan Lee | L8: 375 | M8: Robert Downey Jr. | N8: =INT(C8/10)*10 & "-" & INT(C8/10)*10+9 -> 2010-2019
A9: 4154796 | B9: Avengers: Endgame | C9: 2019 | D9: PG-13 | E9: 181 | F9: 858373000 | G9: Space Sci-Fi | H9: 751577 | I9: Anthony Russo | J9: 498278 | K9: Stan Lee | L9: 262635 | M9: Chris Evans | N9: =INT(C9/10)*10 & "-" & INT(C9/10)*10+9 -> 2010-2019
A10: 4154796 | B10: Avengers: Endgame | C10: 2019 | D10: PG-13 | E10: 181 | F10: 858373000 | G10: Space Sci-Fi | H10: 751577 | I10: Anthony Russo | J10: 498278 | K10: Stan Lee | L10: 749263 | M10: Mark Ruffalo | N10: =INT(C10/10)*10 & "-" & INT(C10/10)*10+9 -> 2010-2019
A11: 4154796 | B11: Avengers: Endgame | C11: 2019 | D11: PG-13 | E11: 181 | F11: 858373000 | G11: Space Sci-Fi | H11: 751648 | I11: Joe Russo | J11: 1321655 | K11: Christopher Markus | L11: 375 | M11: Robert Downey Jr. | N11: =INT(C11/10)*10 & "-" & INT(C11/10)*10+9 -> 2010-2019
A12: 4154796 | B12: Avengers: Endgame | C12: 2019 | D12: PG-13 | E12: 181 | F12: 858373000 | G12: Space Sci-Fi | H12: 751648 | I12: Joe Russo | J12: 1321655 | K12: Christopher Markus | L12: 262635 | M12: Chris Evans | N12: =INT(C12/10)*10 & "-" & INT(C12/10)*10+9 -> 2010-2019
A13: 4154796 | B13: Avengers: Endgame | C13: 2019 | D13: PG-13 | E13: 181 | F13: 858373000 | G13: Space Sci-Fi | H13: 751648 | I13: Joe Russo | J13: 1321655 | K13: Christopher Markus | L13: 749263 | M13: Mark Ruffalo | N13: =INT(C13/10)*10 & "-" & INT(C13/10)*10+9 -> 2010-2019
... A9205: 119698 | B9205: Princess Mononoke | C9205: 1997 | D9205: PG-13 | E9205: 133 | F9205: 11696687 | G9205: Supernatural Fantasy | H9205: 594503 | I9205: Hayao Miyazaki | J9205: 594503 | K9205: Hayao Miyazaki | L9205: 849100 | M9205: Yûko Tanaka | N9205: =INT(C9205/10)*10 & "-" & INT(C9205/10)*10+9 -> 1990-1999
A9206: 82096 | B9206: Das Boot | C9206: 1981 | E9206: 149 | F9206: 11487676 | G9206: Epic | H9206: 583 | I9206: Wolfgang Petersen | J9206: 583 | K9206: Wolfgang Petersen | L9206: 1638 | M9206: Jürgen Prochnow | N9206: =INT(C9206/10)*10 & "-" & INT(C9206/10)*10+9 -> 1980-1989
A9207: 82096 | B9207: Das Boot | C9207: 1981 | E9207: 149 | F9207: 11487676 | G9207: Epic | H9207: 583 | I9207: Wolfgang Petersen | J9207: 583 | K9207: Wolfgang Petersen | L9207: 344963 | M9207: Herbert Grönemeyer | N9207: =INT(C9207/10)*10 & "-" & INT(C9207/10)*10+9 -> 1980-1989
A9208: 82096 | B9208: Das Boot | C9208: 1981 | E9208: 149 | F9208: 11487676 | G9208: Epic | H9208: 583 | I9208: Wolfgang Petersen | J9208: 583 | K9208: Wolfgang Petersen | L9208: 921044 | M9208: Klaus Wennemann | N9208: =INT(C9208/10)*10 & "-" & INT(C9208/10)*10+9 -> 1980-1989
A9209: 82096 | B9209: Das Boot | C9209: 1981 | E9209: 149 | F9209: 11487676 | G9209: Epic | H9209: 583 | I9209: Wolfgang Petersen | J9209: 118164 | K9209: Lothar G. Buchheim | L9209: 1638 | M9209: Jürgen Prochnow | N9209: =INT(C9209/10)*10 & "-" & INT(C9209/10)*10+9 -> 1980-1989
A9210: 82096 | B9210: Das Boot | C9210: 1981 | E9210: 149 | F9210: 11487676 | G9210: Epic | H9210: 583 | I9210: Wolfgang Petersen | J9210: 118164 | K9210: Lothar G. Buchheim | L9210: 344963 | M9210: Herbert Grönemeyer | N9210: =INT(C9210/10)*10 & "-" & INT(C9210/10)*10+9 -> 1980-1989
A9211: 82096 | B9211: Das Boot | C9211: 1981 | E9211: 149 | F9211: 11487676 | G9211: Epic | H9211: 583 | I9211: Wolfgang Petersen | J9211: 118164 | K9211: Lothar G. Buchheim | L9211: 921044 | M9211: Klaus Wennemann | N9211: =INT(C9211/10)*10 & "-" & INT(C9211/10)*10+9 -> 1980-1989
A9212: 82096 | B9212: Das Boot | C9212: 1981 | E9212: 149 | F9212: 11487676 | G9212: War Epic | H9212: 583 | I9212: Wolfgang Petersen | J9212: 583 | K9212: Wolfgang Petersen | L9212: 1638 | M9212: Jürgen Prochnow | N9212: =INT(C9212/10)*10 & "-" & INT(C9212/10)*10+9 -> 1980-1989
A9213: 82096 | B9213: Das Boot | C9213: 1981 | E9213: 149 | F9213: 11487676 | G9213: War Epic | H9213: 583 | I9213: Wolfgang Petersen | J9213: 583 | K9213: Wolfgang Petersen | L9213: 344963 | M9213: Herbert Grönemeyer | N9213: =INT(C9213/10)*10 & "-" & INT(C9213/10)*10+9 -> 1980-1989
A9214: 82096 | B9214: Das Boot | C9214: 1981 | E9214: 149 | F9214: 11487676 | G9214: War Epic | H9214: 583 | I9214: Wolfgang Petersen | J9214: 583 | K9214: Wolfgang Petersen | L9214: 921044 | M9214: Klaus Wennemann | N9214: =INT(C9214/10)*10 & "-" & INT(C9214/10)*10+9 -> 1980-1989
A9215: 82096 | B9215: Das Boot | C9215: 1981 | E9215: 149 | F9215: 11487676 | G9215: War Epic | H9215: 583 | I9215: Wolfgang Petersen | J9215: 118164 | K9215: Lothar G. Buchheim | L9215: 1638 | M9215: Jürgen Prochnow | N9215: =INT(C9215/10)*10 & "-" & INT(C9215/10)*10+9 -> 1980-1989
A9216: 82096 | B9216: Das Boot | C9216: 1981 | E9216: 149 | F9216: 11487676 | G9216: War Epic | H9216: 583 | I9216: Wolfgang Petersen | J9216: 118164 | K9216: Lothar G. Buchheim | L9216: 344963 | M9216: Herbert Grönemeyer | N9216: =INT(C9216/10)*10 & "-" & INT(C9216/10)*10+9 -> 1980-1989
A9217: 82096 | B9217: Das Boot | C9217: 1981 | E9217: 149 | F9217: 11487676 | G9217: War Epic | H9217: 583 | I9217: Wolfgang Petersen | J9217: 118164 | K9217: Lothar G. Buchheim | L9217: 921044 | M9217: Klaus Wennemann | N9217: =INT(C9217/10)*10 & "-" & INT(C9217/10)*10+9 -> 1980-1989
... A9229: 82096 | B9229: Das Boot | C9229: 1981 | E9229: 149 | F9229: 11487676 | G9229: War | H9229: 583 | I9229: Wolfgang Petersen | J9229: 118164 | K9229: Lothar G. Buchheim | L9229: 921044 | M9229: Klaus Wennemann | N9229: =INT(C9229/10)*10 & "-" & INT(C9229/10)*10+9 -> 1980-1989
A9230: 405094 | B9230: The Lives of Others | C9230: 2006 | D9230: R | E9230: 137 | F9230: 11286112 | G9230: Political Thriller | H9230: 3697 | I9230: Florian Henckel von Donnersmarck | J9230: 3697 | K9230: Florian Henckel von Donnersmarck | L9230: 618057 | M9230: Ulrich Mühe | N9230: =INT(C9230/10)*10 & "-" & INT(C9230/10)*10+9 -> 2000-2009
A9231: 405094 | B9231: The Lives of Others | C9231: 2006 | D9231: R | E9231: 137 | F9231: 11286112 | G9231: Political Thriller | H9231: 3697 | I9231: Florian Henckel von Donnersmarck | J9231: 3697 | K9231: Florian Henckel von Donnersmarck | L9231: 311476 | M9231: Martina Gedeck | N9231: =INT(C9231/10)*10 & "-" & INT(C9231/10)*10+9 -> 2000-2009
A9232: 405094 | B9232: The Lives of Others | C9232: 2006 | D9232: R | E9232: 137 | F9232: 11286112 | G9232: Political Thriller | H9232: 3697 | I9232: Florian Henckel von Donnersmarck | J9232: 3697 | K9232: Florian Henckel von Donnersmarck | L9232: 462407 | M9232: Sebastian Koch | N9232: =INT(C9232/10)*10 & "-" & INT(C9232/10)*10+9 -> 2000-2009
A9233: 405094 | B9233: The Lives of Others | C9233: 2006 | D9233: R | E9233: 137 | F9233: 11286112 | G9233: Psychological Drama | H9233: 3697 | I9233: Florian Henckel von Donnersmarck | J9233: 3697 | K9233: Florian Henckel von Donnersmarck | L9233: 618057 | M9233: Ulrich Mühe | N9233: =INT(C9233/10)*10 & "-" & INT(C9233/10)*10+9 -> 2000-2009
A9234: 405094 | B9234: The Lives of Others | C9234: 2006 | D9234: R | E9234: 137 | F9234: 11286112 | G9234: Psychological Drama | H9234: 3697 | I9234: Florian Henckel von Donnersmarck | J9234: 3697 | K9234: Florian Henckel von Donnersmarck | L9234: 311476 | M9234: Martina Gedeck | N9234: =INT(C9234/10)*10 & "-" & INT(C9234/10)*10+9 -> 2000-2009
A9235: 405094 | B9235: The Lives of Others | C9235: 2006 | D9235: R | E9235: 137 | F9235: 11286112 | G9235: Psychological Drama | H9235: 3697 | I9235: Florian Henckel von Donnersmarck | J9235: 3697 | K9235: Florian Henckel von Donnersmarck | L9235: 462407 | M9235: Sebastian Koch | N9235: =INT(C9235/10)*10 & "-" & INT(C9235/10)*10+9 -> 2000-2009
A9236: 405094 | B9236: The Lives of Others | C9236: 2006 | D9236: R | E9236: 137 | F9236: 11286112 | G9236: Spy | H9236: 3697 | I9236: Florian Henckel von Donnersmarck | J9236: 3697 | K9236: Florian Henckel von Donnersmarck | L9236: 618057 | M9236: Ulrich Mühe | N9236: =INT(C9236/10)*10 & "-" & INT(C9236/10)*10+9 -> 2000-2009
A9237: 405094 | B9237: The Lives of Others | C9237: 2006 | D9237: R | E9237: 137 | F9237: 11286112 | G9237: Spy | H9237: 3697 | I9237: Florian Henckel von Donnersmarck | J9237: 3697 | K9237: Florian Henckel von Donnersmarck | L9237: 311476 | M9237: Martina Gedeck | N9237: =INT(C9237/10)*10 & "-" & INT(C9237/10)*10+9 -> 2000-2009
A9238: 405094 | B9238: The Lives of Others | C9238: 2006 | D9238: R | E9238: 137 | F9238: 11286112 | G9238: Spy | H9238: 3697 | I9238: Florian Henckel von Donnersmarck | J9238: 3697 | K9238: Florian Henckel von Donnersmarck | L9238: 462407 | M9238: Sebastian Koch | N9238: =INT(C9238/10)*10 & "-" & INT(C9238/10)*10+9 -> 2000-2009
A9239: 405094 | B9239: The Lives of Others | C9239: 2006 | D9239: R | E9239: 137 | F9239: 11286112 | G9239: Drama | H9239: 3697 | I9239: Florian Henckel von Donnersmarck | J9239: 3697 | K9239: Florian Henckel von Donnersmarck | L9239: 618057 | M9239: Ulrich Mühe | N9239: =INT(C9239/10)*10 & "-" & INT(C9239/10)*10+9 -> 2000-2009
A9240: 405094 | B9240: The Lives of Others | C9240: 2006 | D9240: R | E9240: 137 | F9240: 11286112 | G9240: Drama | H9240: 3697 | I9240: Florian Henckel von Donnersmarck | J9240: 3697 | K9240: Florian Henckel von Donnersmarck | L9240: 311476 | M9240: Martina Gedeck | N9240: =INT(C9240/10)*10 & "-" & INT(C9240/10)*10+9 -> 2000-2009
A9241: 405094 | B9241: The Lives of Others | C9241: 2006 | D9241: R | E9241: 137 | F9241: 11286112 | G9241: Drama | H9241: 3697 | I9241: Florian Henckel von Donnersmarck | J9241: 3697 | K9241: Florian Henckel von Donnersmarck | L9241: 462407 | M9241: Sebastian Koch | N9241: =INT(C9241/10)*10 & "-" & INT(C9241/10)*10+9 -> 2000-2009
... A9988: 87843 | B9988: Once Upon a Time in America | C9988: 1984 | D9988: R | E9988: 229 | F9988: 5321508 | G9988: Drama | H9988: 1466 | I9988: Sergio Leone | J9988: 207401 | K9988: Piero De Bernardi | L9988: 1527 | M9988: Elizabeth McGovern | N9988: =INT(C9988/10)*10 & "-" & INT(C9988/10)*10+9 -> 1980-1989
...

Sheet Chart
A2: Row Labels | B2: Average of gross_us_canada
A3: Avengers: Endgame | B3: 858373000
A4: Spider-Man: No Way Home | B4: 814866759
A5: Top Gun: Maverick | B5: 718732821
A6: Avengers: Infinity War | B6: 678815482
A7: The Dark Knight | B7: 534987076
A8: Star Wars: Episode IV - A New Hope | B8: 460998507
A9: The Dark Knight Rises | B9: 448149584
A10: The Lion King | B10: 424979720
A11: Toy Story 3 | B11: 415004880
A12: Jurassic Park | B12: 407185075
A13: Grand Total | B13: 5.8148293e+08
A18: Row Labels | B18: Distinct Count of title
A19: Robert De Niro | B19: 9
A20: Tom Hanks | B20: 6
A21: Harrison Ford | B21: 6
A22: Leonardo DiCaprio | B22: 6
A23: Charles Chaplin | B23: 5
A24: Grand Total | B24: 31
A33: Row Labels | B33: Distinct Count of title
A34: R | B34: 102
A35: PG | B35: 38
A36: PG-13 | B36: 35
A37: Not Rated | B37: 23
A38: Approved | B38: 21
A39: G | B39: 18
A40: (blank) | B40: 6
A41: Passed | B41: 5
A42: TV-MA | B42: 1
A43: NC-17 | B43: 1
A44: Grand Total | B44: 250
A50: Distinct Count of title | B50: Column Labels
A51: Row Labels | B51: R | C51: PG | D51: PG-13 | E51: Not Rated | F51: Approved | G51: G | H51: (blank) | I51: Passed | J51: TV-MA | K51: NC-17 | L51: Grand Total
A52: Action | B52: 17 | C52: 7 | D52: 14 | E52: 4 | H52: 2 | I52: 2 | J52: 1 | L52: 47
A53: Action Epic | B53: 8 | C53: 6 | D53: 12 | E53: 1 | L53: 27
A54: Adult Animation | B54: 1 | D54: 1 | E54: 3 | J54: 1 | L54: 6
A55: Adventure | B55: 10 | C55: 18 | D55: 13 | E55: 1 | F55: 4 | G55: 11 | I55: 1 | J55: 1 | L55: 59
A56: Adventure Epic | B56: 4 | C56: 7 | D56: 8 | G56: 5 | L56: 24
A57: Alien Invasion | B57: 3 | C57: 1 | L57: 4
A58: Animal Adventure | C58: 1 | G58: 4 | L58: 5
...

Sheet Report Chart
A2: IMDb Top 250 movies
B18: Top 5 Actors with the Most Appearances in IMDb Top 250 Movies
B19: Actor | G19: Number Of Appearances
B20: =Chart!$A19 -> Robert De Niro | G20: =GETPIVOTDATA("[Measures].[Distinct Count of title]",Chart!$A$18,"[Table2_1].[star.star]","[Table2_1].[star.star].&[Robert De Niro]") -> 9
B21: =Chart!$A20 -> Tom Hanks | G21: =GETPIVOTDATA("[Measures].[Distinct Count of title]",Chart!$A$18,"[Table2_1].[star.star]","[Table2_1].[star.star].&[Tom Hanks]") -> 6
B22: =Chart!$A21 -> Harrison Ford | G22: =GETPIVOTDATA("[Measures].[Distinct Count of title]",Chart!$A$18,"[Table2_1].[star.star]","[Table2_1].[star.star].&[Leonardo DiCaprio]") -> 6
B23: =Chart!$A22 -> Leonardo DiCaprio | G23: =GETPIVOTDATA("[Measures].[Distinct Count of title]",Chart!$A$18,"[Table2_1].[star.star]","[Table2_1].[star.star].&[Leonardo DiCaprio]") -> 6
B24: =Chart!$A23 -> Charles Chaplin | G24: =GETPIVOTDATA("[Measures].[Distinct Count of title]",Chart!$A$18,"[Table2_1].[star.star]","[Table2_1].[star.star].&[Charles Chaplin]") -> 5
B26: Number of films in each parental guide among the top 250 films on IMDB
B27: Parental Guide | G27: Number Of Movies
B28: =Chart!$A34 -> R | G28: =GETPIVOTDATA("[Measures].[Distinct Count of title]",Chart!$A$33,"[Table2_1].[parental_guide]","[Table2_1].[parental_guide].&[R]") -> 102
B29: =Chart!$A35 -> PG | G29: =GETPIVOTDATA("[Measures].[Distinct Count of title]",Chart!$A$33,"[Table2_1].[parental_guide]","[Table2_1].[parental_guide].&[PG]") -> 38
B30: =Chart!$A36 -> PG-13 | G30: =GETPIVOTDATA("[Measures].[Distinct Count of title]",Chart!$A$33,"[Table2_1].[parental_guide]","[Table2_1].[parental_guide].&[PG-13]") -> 35
B31: =Chart!$A37 -> Not Rated | G31: =GETPIVOTDATA("[Measures].[Distinct Count of title]",Chart!$A$33,"[Table2_1].[parental_guide]","[Table2_1].[parental_guide].&[Not Rated]") -> 23
B32: =Chart!$A38 -> Approved | G32: =GETPIVOTDATA("[Measures].[Distinct Count of title]",Chart!$A$33,"[Table2_1].[parental_guide]","[Table2_1].[parental_guide].&[Approved]") -> 21
B33: =Chart!$A39 -> G | G33: =GETPIVOTDATA("[Measures].[Distinct Count of title]",Chart!$A$33,"[Table2_1].[parental_guide]","[Table2_1].[parental_guide].&[G]") -> 18
B34: Without Parental Guide | G34: =GETPIVOTDATA("[Measures].[Distinct Count of title]",Chart!$A$33,"[Table2_1].[parental_guide]","[Table2_1].[parental_guide].&") -> 6
B35: =Chart!$A41 -> Passed | G35: =GETPIVOTDATA("[Measures].[Distinct Count of title]",Chart!$A$33,"[Table2_1].[parental_guide]","[Table2_1].[parental_guide].&[Passed]") -> 5
B36: =Chart!$A42 -> TV-MA | G36: =GETPIVOTDATA("[Measures].[Distinct Count of title]",Chart!$A$33,"[Table2_1].[parental_guide]","[Table2_1].[parental_guide].&[TV-MA]") -> 1
B37: =Chart!$A43 -> NC-17 | G37: =GETPIVOTDATA("[Measures].[Distinct Count of title]",Chart!$A$33,"[Table2_1].[parental_guide]","[Table2_1].[parental_guide].&[NC-17]") -> 1
B39: Number of each parental Guide in each genre among the top 250 movies on IMDB
F41: Count of title | G41: Parental Guide
F42: Genre | G42: Approved | H42: G | I42: NC-17 | J42: Not Rated | K42: Without PG | L42: Passed | M42: PG | N42: PG-13 | O42: R | P42: TV-MA | Q42: Grand Total
F43: Action | J43: 4 | K43: 2 | L43: 2 | M43: 7 | N43: 14 | O43: 17 | P43: 1 | Q43: 47
F44: Action Epic | J44: 1 | M44: 6 | N44: 12 | O44: 8 | Q44: 27
F45: Adult Animation | J45: 3 | N45: 1 | O45: 1 | P45: 1 | Q45: 6
F46: Adventure | G46: 4 | H46: 11 | J46: 1 | L46: 1 | M46: 18 | N46: 13 | O46: 10 | P46: 1 | Q46: 59
F47: Adventure Epic | H47: 5 | M47: 7 | N47: 8 | O47: 4 | Q47: 24
F48: Alien Invasion | M48: 1 | O48: 3 | Q48: 4
F49: Animal Adventure | H49: 4 | M49: 1 | Q49: 5
F50: Animation | H50: 8 | J50: 3 | K50: 2 | M50: 11 | O50: 1 | Q50: 25
F51: Anime | H51: 1 | J51: 2 | K51: 2 | M51: 2 | N51: 1 | O51: 1 | P51: 1 | Q51: 10
F52: Artificial Intelligence | H52: 2 | M52: 2 | O52: 4 | Q52: 8
F53: Biography | H53: 2 | J53: 1 | K53: 1 | L53: 1 | M53: 3 | N53: 6 | O53: 14 | Q53: 28
F54: Body Horror | O54: 3 | Q54: 3
F55: Boxing | M55: 1 | N55: 2 | O55: 1 | Q55: 4
F56: Buddy Comedy | G56: 1 | H56: 4 | L56: 1 | M56: 2 | N56: 1 | O56: 2 | Q56: 11
F57: Bumbling Detective | L57: 1 | Q57: 1
F58: Caper | M58: 1 | N58: 1 | O58: 3 | Q58: 5
F59: Car Action | N59: 1 | O59: 1 | Q59: 2
...

Sheet Intractive Chart
A2: IMDb Top 250 movies
